(window.webpackJsonp=window.webpackJsonp||[]).push([[25],{163:function(e,t,a){"use strict";a.r(t);var n=a(0),o=Object(n.a)({},function(){this.$createElement;this._self._c;return this._m(0)},[function(){var e=this,t=e.$createElement,a=e._self._c||t;return a("div",{staticClass:"content"},[a("h1",{attrs:{id:"exception-handling"}},[a("a",{staticClass:"header-anchor",attrs:{href:"#exception-handling","aria-hidden":"true"}},[e._v("#")]),e._v(" Exception Handling")]),e._v(" "),a("p",[e._v("In this article, you will learn about Exception Handling in C++ and which handle run time error.")]),e._v(" "),a("h2",{attrs:{id:"exception-handling-is-the-mechanism-that-separate-the-code-that-detects-and-handle-exceptions-at-run-time-from-rest-of-program"}},[a("a",{staticClass:"header-anchor",attrs:{href:"#exception-handling-is-the-mechanism-that-separate-the-code-that-detects-and-handle-exceptions-at-run-time-from-rest-of-program","aria-hidden":"true"}},[e._v("#")]),e._v(" Exception Handling is the mechanism that separate the code that detects and handle exceptions at run time from rest of program")]),e._v(" "),a("p",[e._v("C++ exception handling is built upon three keywords: try, catch, and throw.")]),e._v(" "),a("p",[e._v("Exception Handling vs Traditional Error Handling")]),e._v(" "),a("p",[e._v("Following are main advantages of exception handling over traditional error handling.")]),e._v(" "),a("h3",{attrs:{id:"_1-separation-of-error-handling-code-from-normal-code"}},[a("a",{staticClass:"header-anchor",attrs:{href:"#_1-separation-of-error-handling-code-from-normal-code","aria-hidden":"true"}},[e._v("#")]),e._v(" 1. Separation of Error Handling code from Normal Code:")]),e._v(" "),a("p",[e._v("In traditional error handling codes, there are always if else conditions to handle errors. These conditions and the code to handle errors get mixed up with the normal flow. This makes the code less readable and maintainable. With try catch blocks, the code for error handling becomes separate from the normal flow.")]),e._v(" "),a("p",[a("ins",{staticClass:"adsbygoogle",staticStyle:{display:"block","text-align":"center"},attrs:{"data-ad-layout":"in-article","data-ad-format":"fluid","data-ad-client":"ca-pub-6356177594937247","data-ad-slot":"2874230806"}}),e._v(" "),a("script",[e._v("\n(adsbygoogle = window.adsbygoogle || []).push({});\n")])]),e._v(" "),a("h3",{attrs:{id:"_2-functions-methods-can-handle-any-exceptions-they-choose"}},[a("a",{staticClass:"header-anchor",attrs:{href:"#_2-functions-methods-can-handle-any-exceptions-they-choose","aria-hidden":"true"}},[e._v("#")]),e._v(" 2. Functions/Methods can handle any exceptions they choose:")]),e._v(" "),a("p",[e._v("A function can throw many exceptions, but may choose to handle some of them. The other exceptions which are thrown, but not caught can be handled by caller. If the caller chooses not to catch them, then the exceptions are handled by caller of the caller.\nIn C++, a function can specify the exceptions that it throws using the throw keyword. The caller of this function must handle the exception in some way (either by specifying it again or catching it)")]),e._v(" "),a("h3",{attrs:{id:"_3-grouping-of-error-types"}},[a("a",{staticClass:"header-anchor",attrs:{href:"#_3-grouping-of-error-types","aria-hidden":"true"}},[e._v("#")]),e._v(" 3.  Grouping of Error Types:")]),e._v(" "),a("p",[e._v("In C++, both basic types and objects can be thrown as exception. We can create a hierarchy of exception objects, group exceptions in namespaces or classes, categorize them according to types.")]),e._v(" "),a("h2",{attrs:{id:"exception-handling-model"}},[a("a",{staticClass:"header-anchor",attrs:{href:"#exception-handling-model","aria-hidden":"true"}},[e._v("#")]),e._v(" Exception Handling Model")]),e._v(" "),a("p",[e._v("The error handling mechanism perform following task :")]),e._v(" "),a("ul",[a("li",[e._v("Find the problem (Hit the Exception)")]),e._v(" "),a("li",[e._v("Inform that error has occured (Throw the exception)")]),e._v(" "),a("li",[e._v("Receive the error information (Catch the exception)")]),e._v(" "),a("li",[e._v("Take corrective ations (Handle the exception)")])]),e._v(" "),a("img",{attrs:{src:"https://1.bp.blogspot.com/-7-cFx7t0GQg/WPOHfF4FoEI/AAAAAAAAAi8/M8CVmjoGzssNx3vB8pL7nYptUADiNv3vACPcB/s1600/What%2Bis%2BException%2BHandling%2Bin%2BC%252B%252B%2B1.jpg"}}),e._v(" "),a("h2",{attrs:{id:"try-block"}},[a("a",{staticClass:"header-anchor",attrs:{href:"#try-block","aria-hidden":"true"}},[e._v("#")]),e._v(" Try Block")]),e._v(" "),a("p",[e._v('A try/catch block is placed around the code for which particular exception will be analysed and detected.It is followed by one or more catch blocks . The try block doesn\'t define how we are handling an exception but it merely tells the program , "if you see an exception in the following code , grab it". If the try block detects exception , the exception is thrown to catch block using throw keyword and program control also transfer to catch block , it never returns to try blocks again. If no error is found within try block , catch block is escaped .')]),e._v(" "),a("p",[e._v("Syntax:")]),e._v(" "),a("div",{staticClass:"language-c line-numbers-mode"},[a("pre",{pre:!0,attrs:{class:"language-c"}},[a("code",[e._v("try\n"),a("span",{attrs:{class:"token punctuation"}},[e._v("{")]),e._v("\n"),a("span",{attrs:{class:"token comment"}},[e._v("//code to be monitered.")]),e._v("\n"),a("span",{attrs:{class:"token punctuation"}},[e._v("}")]),e._v("\n\n")])]),e._v(" "),a("div",{staticClass:"line-numbers-wrapper"},[a("span",{staticClass:"line-number"},[e._v("1")]),a("br"),a("span",{staticClass:"line-number"},[e._v("2")]),a("br"),a("span",{staticClass:"line-number"},[e._v("3")]),a("br"),a("span",{staticClass:"line-number"},[e._v("4")]),a("br"),a("span",{staticClass:"line-number"},[e._v("5")]),a("br")])]),a("h2",{attrs:{id:"throw-block"}},[a("a",{staticClass:"header-anchor",attrs:{href:"#throw-block","aria-hidden":"true"}},[e._v("#")]),e._v(" Throw Block")]),e._v(" "),a("p",[e._v("An exception is thrown in a particular catch block using throw keyword. It can throw object of different types , known as exception objects.")]),e._v(" "),a("p",[e._v("When try blocks is executed , whenever exceptions are found they are thrown through throw blocks and the program leaves the try block and enters into the catch blocks . If type of object thrown in try block match the argument type in the catch statement ,\nthe catch block are executed to handle those exception . If no match catch are found , then program is aborted with the help of abort() function which is invoked by default\nCatch Block")]),e._v(" "),a("p",[e._v("The catch block following the try block catches any exception. You can specify what type of exception you want to catch and this is determined by the exception declaration that appears in parentheses following the keyword catch.")]),e._v(" "),a("p",[e._v("Syntax")]),e._v(" "),a("div",{staticClass:"language-c line-numbers-mode"},[a("pre",{pre:!0,attrs:{class:"language-c"}},[a("code",[e._v("catch "),a("span",{attrs:{class:"token punctuation"}},[e._v("(")]),a("span",{attrs:{class:"token punctuation"}},[e._v(")")]),e._v("\n"),a("span",{attrs:{class:"token punctuation"}},[e._v("{")]),e._v("\n"),a("span",{attrs:{class:"token comment"}},[e._v("//block of statement that handles the exception")]),e._v("\n"),a("span",{attrs:{class:"token punctuation"}},[e._v("}")]),e._v("\n")])]),e._v(" "),a("div",{staticClass:"line-numbers-wrapper"},[a("span",{staticClass:"line-number"},[e._v("1")]),a("br"),a("span",{staticClass:"line-number"},[e._v("2")]),a("br"),a("span",{staticClass:"line-number"},[e._v("3")]),a("br"),a("span",{staticClass:"line-number"},[e._v("4")]),a("br")])]),a("h2",{attrs:{id:"rethrowing-an-exception"}},[a("a",{staticClass:"header-anchor",attrs:{href:"#rethrowing-an-exception","aria-hidden":"true"}},[e._v("#")]),e._v(" Rethrowing an Exception")]),e._v(" "),a("p",[e._v("If a catch block cannot handle the particular exception it has caught, you can rethrow the exception. The rethrow expression (throw without assignment_expression) causes the originally thrown object to be rethrown.")]),e._v(" "),a("p",[e._v("Because the exception has already been caught at the scope in which the rethrow expression occurs, it is rethrown out to the next dynamically enclosing try block. Therefore, it cannot be handled by catch blocks at the scope in which the rethrow expression occurred. Any catch blocks for the dynamically enclosing try block have an opportunity to catch the exception.")])])}],!1,null,null,null);o.options.__file="exception-handling-c-language.md";t.default=o.exports}}]);